##19:40:37 12/06/2016 - Exception on /datareceiver [POST]
Traceback (most recent call last):
  File "/home/nikita/develop/flask_project/logapp/env/local/lib/python2.7/site-packages/flask/app.py", line 1988, in wsgi_app
    response = self.full_dispatch_request()
  File "/home/nikita/develop/flask_project/logapp/env/local/lib/python2.7/site-packages/flask/app.py", line 1641, in full_dispatch_request
    rv = self.handle_user_exception(e)
  File "/home/nikita/develop/flask_project/logapp/env/local/lib/python2.7/site-packages/flask/app.py", line 1544, in handle_user_exception
    reraise(exc_type, exc_value, tb)
  File "/home/nikita/develop/flask_project/logapp/env/local/lib/python2.7/site-packages/flask/app.py", line 1639, in full_dispatch_request
    rv = self.dispatch_request()
  File "/home/nikita/develop/flask_project/logapp/env/local/lib/python2.7/site-packages/flask/app.py", line 1625, in dispatch_request
    return self.view_functions[rule.endpoint](**req.view_args)
  File "/home/nikita/develop/flask_project/logapp/app/views.py", line 106, in equipments
    raise ValueError;
ValueError
##19:42:51 12/06/2016 - Exception on /datareceiver [POST]
Traceback (most recent call last):
  File "/home/nikita/develop/flask_project/logapp/env/local/lib/python2.7/site-packages/flask/app.py", line 1988, in wsgi_app
    response = self.full_dispatch_request()
  File "/home/nikita/develop/flask_project/logapp/env/local/lib/python2.7/site-packages/flask/app.py", line 1641, in full_dispatch_request
    rv = self.handle_user_exception(e)
  File "/home/nikita/develop/flask_project/logapp/env/local/lib/python2.7/site-packages/flask/app.py", line 1544, in handle_user_exception
    reraise(exc_type, exc_value, tb)
  File "/home/nikita/develop/flask_project/logapp/env/local/lib/python2.7/site-packages/flask/app.py", line 1639, in full_dispatch_request
    rv = self.dispatch_request()
  File "/home/nikita/develop/flask_project/logapp/env/local/lib/python2.7/site-packages/flask/app.py", line 1625, in dispatch_request
    return self.view_functions[rule.endpoint](**req.view_args)
  File "/home/nikita/develop/flask_project/logapp/app/views.py", line 106, in equipments
    raise ValueError;
ValueError
##19:40:37 12/06/2016 - Exception on /datareceiver [POST]
Traceback (most recent call last):
  File "/home/nikita/develop/flask_project/logapp/env/local/lib/python2.7/site-packages/flask/app.py", line 1988, in wsgi_app
    response = self.full_dispatch_request()
  File "/home/nikita/develop/flask_project/logapp/env/local/lib/python2.7/site-packages/flask/app.py", line 1641, in full_dispatch_request
    rv = self.handle_user_exception(e)
  File "/home/nikita/develop/flask_project/logapp/env/local/lib/python2.7/site-packages/flask/app.py", line 1544, in handle_user_exception
    reraise(exc_type, exc_value, tb)
  File "/home/nikita/develop/flask_project/logapp/env/local/lib/python2.7/site-packages/flask/app.py", line 1639, in full_dispatch_request
    rv = self.dispatch_request()
  File "/home/nikita/develop/flask_project/logapp/env/local/lib/python2.7/site-packages/flask/app.py", line 1625, in dispatch_request
    return self.view_functions[rule.endpoint](**req.view_args)
  File "/home/nikita/develop/flask_project/logapp/app/views.py", line 106, in equipments
    raise ValueError;
TypeError
##19:40:37 13/06/2016 - Exception on /datareceiver [POST]
Traceback (most recent call last):
  File "/home/nikita/develop/flask_project/logapp/env/local/lib/python2.7/site-packages/flask/app.py", line 1988, in wsgi_app
    response = self.full_dispatch_request()
  File "/home/nikita/develop/flask_project/logapp/env/local/lib/python2.7/site-packages/flask/app.py", line 1641, in full_dispatch_request
    rv = self.handle_user_exception(e)
  File "/home/nikita/develop/flask_project/logapp/env/local/lib/python2.7/site-packages/flask/app.py", line 1544, in handle_user_exception
    reraise(exc_type, exc_value, tb)
  File "/home/nikita/develop/flask_project/logapp/env/local/lib/python2.7/site-packages/flask/app.py", line 1639, in full_dispatch_request
    rv = self.dispatch_request()
  File "/home/nikita/develop/flask_project/logapp/env/local/lib/python2.7/site-packages/flask/app.py", line 1625, in dispatch_request
    return self.view_functions[rule.endpoint](**req.view_args)
  File "/home/nikita/develop/flask_project/logapp/app/views.py", line 106, in equipments
    raise ValueError;
TypeError
##03:53:45 13/06/2016 - Exception on / [GET]
Traceback (most recent call last):
  File "/home/nikita/develop/flask_project/logapp/env/local/lib/python2.7/site-packages/flask/app.py", line 1988, in wsgi_app
    response = self.full_dispatch_request()
  File "/home/nikita/develop/flask_project/logapp/env/local/lib/python2.7/site-packages/flask/app.py", line 1641, in full_dispatch_request
    rv = self.handle_user_exception(e)
  File "/home/nikita/develop/flask_project/logapp/env/local/lib/python2.7/site-packages/flask/app.py", line 1544, in handle_user_exception
    reraise(exc_type, exc_value, tb)
  File "/home/nikita/develop/flask_project/logapp/env/local/lib/python2.7/site-packages/flask/app.py", line 1639, in full_dispatch_request
    rv = self.dispatch_request()
  File "/home/nikita/develop/flask_project/logapp/env/local/lib/python2.7/site-packages/flask/app.py", line 1625, in dispatch_request
    return self.view_functions[rule.endpoint](**req.view_args)
  File "/home/nikita/develop/flask_project/logapp/app/views.py", line 80, in index
    raise UnicodeError
UnicodeError
##03:56:27 13/06/2016 - Exception on /datareceiver [POST]
Traceback (most recent call last):
  File "/home/nikita/develop/flask_project/logapp/env/local/lib/python2.7/site-packages/flask/app.py", line 1988, in wsgi_app
    response = self.full_dispatch_request()
  File "/home/nikita/develop/flask_project/logapp/env/local/lib/python2.7/site-packages/flask/app.py", line 1641, in full_dispatch_request
    rv = self.handle_user_exception(e)
  File "/home/nikita/develop/flask_project/logapp/env/local/lib/python2.7/site-packages/flask/app.py", line 1544, in handle_user_exception
    reraise(exc_type, exc_value, tb)
  File "/home/nikita/develop/flask_project/logapp/env/local/lib/python2.7/site-packages/flask/app.py", line 1639, in full_dispatch_request
    rv = self.dispatch_request()
  File "/home/nikita/develop/flask_project/logapp/env/local/lib/python2.7/site-packages/flask/app.py", line 1625, in dispatch_request
    return self.view_functions[rule.endpoint](**req.view_args)
  File "/home/nikita/develop/flask_project/logapp/app/views.py", line 91, in equipments
    raise FileExistsError
NameError: global name 'FileExistsError' is not defined
